Workbook
Name Base_FY_Operating_Result: Forecast!$H$5
Name Bear_FY_Operating_Result: Forecast!$H$6
Name BTC_Price_Input: Inputs!$H$5
Name Swing: Forecast!$H$7

Sheet Read Me
A1: Blockstream Finance - FP&A Case Study Model
A2: Prepared by Shakil Ahmad, CFA · Data: fully synthetic case pack ("today" = June 9, 2026, May close done) · All $ in $000s
A4: START HERE | B4: Flip Inputs!H5 (BTC price, yellow) - Liquid fee revenue, the treasury mark, and all three scenario cells (Forecast!H5:H7: Base FY Operating Result, Bear FY Operating Result, Swing) recalculate. No BTC price is hardcoded anywhere else; the bear case derives from the same cell via the Inputs!H6 shock.
A6: TAB GUIDE
A7: Inputs | B7: Every assumption and driver. Blue-on-yellow = judgment inputs; black = derived from Jan–May actuals by live formula; green = links to source data.
A8: BvA | B8: Segment P&L (contribution margin) to operating profit; May + YTD actual vs budget with $/% variances and materiality flags (≥$50K and ≥10%). Treasury mark shown below operating profit as a reconciling line, with the why.
A9: Forecast | B9: Driver-based Jun–Dec, base and bear side by side from the single BTC cell. FY columns splice Jan–May actuals with the forecast.
A10: GL_Recon | B10: Five GL accounts reconciled to the reported P&L: one footing break (duplicate invoice), two accounts that foot but are wrong (cut-off, rev-rec), two confirmed clean. Correcting entries, impacts, controls, corrected-May view.
A11: Tie-Out | B11: Six reviewer-relevant figures: model cell vs independent recompute from raw data. All rows must read TIE.
A12: Alloc_View | B12: Rejected-alternative sensitivity: full OpEx allocation by headcount.
A13: Decision_Log | B13: Five modeling decisions with driving cells and priced alternatives.
A14: Data_* / GL_Detail | B14: Untouched replicas of the source pack - the only value-typed tabs. Everything else is formulas.
A16: COLOR LEGEND | B16: Blue = hardcoded input · Black = formula · Green = cross-sheet link · Yellow fill = key inputs / labeled scenario cells
A17: SIGN CONVENTION | B17: Costs shown as positive magnitudes and subtracted in formulas; BTC treasury mark signed (negative = mark-down), as in the source pack.

Sheet Inputs
A1: Inputs & Drivers - every forecast assumption lives here
A2: Blue on yellow = judgment inputs (edit these). Black = derived from Jan–May actuals by formula. Green = link to source data. All $ in $000s.
A4: BTC PRICE SCENARIO - THE cell (flows to Liquid fees, treasury mark, base & bear cases) | C4: Jan | D4: Feb | E4: Mar | F4: Apr | G4: May | H4: Assumptions | K4: Historical metric / support
A5: BTC price assumption, Jun–Dec 2026 (flat path) | C5: =Data_KPIs!C5 -> 94000 | D5: =Data_KPIs!D5 -> 88000 | E5: =Data_KPIs!E5 -> 101000 | F5: =Data_KPIs!F5 -> 92000 | G5: =Data_KPIs!G5 -> 108000 | H5: 108000 | I5: Base = May 2026 monthly average (Data_KPIs). Flip this cell - everything recalculates. | K5: BTC price ($)
A6: Bear-case shock to the BTC assumption | H6: -0.5 | I6: Bear price is derived: base cell × (1 + shock). No second BTC price is typed anywhere. | K6: Scenario assumption - no historical series
A7: Bear-case BTC price (derived) | H7: =H5*(1+H6) -> 54000 | K7: Derived scenario output - no historical series
A8: Corporate BTC treasury holdings (BTC) | C8: n/a | D8: =Data_Actuals!E11*1000/(Data_KPIs!D5-Data_KPIs!C5) -> 70 | E8: =Data_Actuals!F11*1000/(Data_KPIs!E5-Data_KPIs!D5) -> 84.615385 | F8: =Data_Actuals!G11*1000/(Data_KPIs!F5-Data_KPIs!E5) -> 75.555556 | G8: =Data_Actuals!H11*1000/(Data_KPIs!G5-Data_KPIs!F5) -> 90.625 | H8: 80 | I8: Implied from actuals: monthly MTM ÷ Δ avg BTC price ranges 70–91 BTC (see derivation, C8:G8 on this row). 80 used; stated assumption. | K8: Implied BTC held from MTM / change in BTC price
A10: REVENUE DRIVERS (derived from Jan–May actuals unless blue)
A11: Jade units - monthly growth Jun–Dec | C11: n/a | D11: =Data_KPIs!D6/Data_KPIs!C6-1 -> -0.064516129 | E11: =Data_KPIs!E6/Data_KPIs!D6-1 -> 0.22413793 | F11: =Data_KPIs!F6/Data_KPIs!E6-1 -> -0.23943662 | G11: =Data_KPIs!G6/Data_KPIs!F6-1 -> -0.082962963 | H11: 0 | I11: Judgment: hold May run-rate (6,190 units) flat. Units fell 20% Jan→May vs a rising budget; the budget ramp is not evidence-based. Decision Log #4. | K11: Jade units - monthly growth
A12: Jade ASP ($) | C12: =Data_KPIs!C7 -> 80 | D12: =Data_KPIs!D7 -> 80 | E12: =Data_KPIs!E7 -> 80 | F12: =Data_KPIs!F7 -> 80 | G12: =Data_KPIs!G7 -> 80 | H12: =Data_KPIs!$G$7 -> 80 | I12: Constant $80 all five months. | K12: Jade ASP ($)
A13: Store & Accessories as % of Jade revenue | C13: =Data_Actuals!D7/Data_Actuals!D5 -> 0.15322581 | D13: =Data_Actuals!E7/Data_Actuals!E5 -> 0.15172414 | E13: =Data_Actuals!F7/Data_Actuals!F5 -> 0.15492958 | F13: =Data_Actuals!G7/Data_Actuals!G5 -> 0.14814815 | G13: =Data_Actuals!H7/Data_Actuals!H5 -> 0.15353535 | H13: =AVERAGE(Data_Actuals!D7:H7)/AVERAGE(Data_Actuals!D5:H5) -> 0.1524618 | I13: Stable ~15.3% of Jade revenue Jan–May; attach-rate relationship. | K13: Store revenue as % of Jade revenue
A14: App & Subscriptions - monthly growth | C14: n/a | D14: =Data_Actuals!E6/Data_Actuals!D6-1 -> 0.038095238 | E14: =Data_Actuals!F6/Data_Actuals!E6-1 -> 0.032110092 | F14: =Data_Actuals!G6/Data_Actuals!F6-1 -> 0.035555556 | G14: =Data_Actuals!H6/Data_Actuals!G6-1 -> 0.030042918 | H14: =(Data_Actuals!$H$6/Data_Actuals!$D$6)^(1/4)-1 -> 0.033946308 | I14: CAGR of actuals Jan→May (~3.4%/mo). | K14: App revenue - monthly growth
A15: Liquid pegged-in BTC - monthly growth | C15: n/a | D15: =Data_KPIs!D9/Data_KPIs!C9-1 -> 0.035714286 | E15: =Data_KPIs!E9/Data_KPIs!D9-1 -> 0.029885057 | F15: =Data_KPIs!F9/Data_KPIs!E9-1 -> 0.03125 | G15: =Data_KPIs!G9/Data_KPIs!F9-1 -> 0.041125541 | H15: =(Data_KPIs!$G$9/Data_KPIs!$C$9)^(1/4)-1 -> 0.034484401 | I15: CAGR of pegged-in BTC Jan→May (~3.4%/mo). | K15: Liquid pegged-in BTC - monthly growth
A16: Liquid fee yield on TVL (monthly) | C16: =Data_Actuals!D8/(Data_KPIs!C9*Data_KPIs!C5/1000) -> 0.00096251266 | D16: =Data_Actuals!E8/(Data_KPIs!D9*Data_KPIs!D5/1000) -> 0.00091431557 | E16: =Data_Actuals!F8/(Data_KPIs!E9*Data_KPIs!E5/1000) -> 0.00098346888 | F16: =Data_Actuals!G8/(Data_KPIs!F9*Data_KPIs!F5/1000) -> 0.0009528515 | G16: =Data_Actuals!H8/(Data_KPIs!G9*Data_KPIs!G5/1000) -> 0.00098175098 | H16: =(Data_Actuals!$D$8/(Data_KPIs!$C$9*Data_KPIs!$C$5/1000)+Data_Actuals!$E$8/(Data_KPIs!$D$9*Data_KPIs!$D$5/1000)+Data_Actuals!$F$8/(Data_KPIs!$E$9*Data_KPIs!$E$5/1000)+Data_Actuals!$G$8/(Data_KPIs!$F$9*Data_KPIs!$F$5/1000)+Data_Actuals!$H$8/(Data_KPIs!$G$9*Data_KPIs!$G$5/1000))/5 -> 0.00095897992 | I16: KEY INSIGHT: fees ÷ (pegged-in BTC × avg price) is nearly constant ~0.096%/mo across all 5 months (min–max on row 17). Fee revenue is TVL × yield - this is how the BTC cell reaches an operating line. | K16: Liquid fee yield on TVL
A17: yield stability check (min | max of 5 months) | C17: =Data_Actuals!D8/(Data_KPIs!C9*Data_KPIs!C5/1000) -> 0.00096251266 | D17: =Data_Actuals!E8/(Data_KPIs!D9*Data_KPIs!D5/1000) -> 0.00091431557 | E17: =Data_Actuals!F8/(Data_KPIs!E9*Data_KPIs!E5/1000) -> 0.00098346888 | F17: =Data_Actuals!G8/(Data_KPIs!F9*Data_KPIs!F5/1000) -> 0.0009528515 | G17: =Data_Actuals!H8/(Data_KPIs!G9*Data_KPIs!G5/1000) -> 0.00098175098 | H17: =MIN(Data_Actuals!$D$8/(Data_KPIs!$C$9*Data_KPIs!$C$5/1000),Data_Actuals!$E$8/(Data_KPIs!$D$9*Data_KPIs!$D$5/1000),Data_Actuals!$F$8/(Data_KPIs!$E$9*Data_KPIs!$E$5/1000),Data_Actuals!$G$8/(Data_KPIs!$F$9*Data_KPIs!$F$5/1000),Data_Actuals!$H$8/(Data_KPIs!$G$9*Data_KPIs!$G$5/1000)) -> 0.00091431557 | J17: =MAX(Data_Actuals!$D$8/(Data_KPIs!$C$9*Data_KPIs!$C$5/1000),Data_Actuals!$E$8/(Data_KPIs!$D$9*Data_KPIs!$D$5/1000),Data_Actuals!$F$8/(Data_KPIs!$E$9*Data_KPIs!$E$5/1000),Data_Actuals!$G$8/(Data_KPIs!$F$9*Data_KPIs!$F$5/1000),Data_Actuals!$H$8/(Data_KPIs!$G$9*Data_KPIs!$G$5/1000)) -> 0.00098346888 | K17: Monthly values supporting min / max check
A18: AMP (SaaS) - monthly $ adds | C18: n/a | D18: =Data_Actuals!E9-Data_Actuals!D9 -> 30 | E18: =Data_Actuals!F9-Data_Actuals!E9 -> 30 | F18: =Data_Actuals!G9-Data_Actuals!F9 -> 35 | G18: =Data_Actuals!H9-Data_Actuals!G9 -> 35 | H18: =(Data_Actuals!$H$9-Data_Actuals!$D$9)/4 -> 32.5 | I18: Linear +$32.5K/mo Jan–May. Reported basis; see GL_Recon for the $132K rev-rec adjustment. | K18: AMP revenue - monthly dollar adds ($000s)
A19: Enterprise Infra & Licensing - monthly $ adds | C19: n/a | D19: =Data_Actuals!E10-Data_Actuals!D10 -> 15 | E19: =Data_Actuals!F10-Data_Actuals!E10 -> -35 | F19: =Data_Actuals!G10-Data_Actuals!F10 -> 60 | G19: =Data_Actuals!H10-Data_Actuals!G10 -> 25 | H19: =(Data_Actuals!$H$10-Data_Actuals!$D$10)/4 -> 16.25 | I19: Linear +$16.3K/mo Jan–May. | K19: Enterprise Infra revenue - monthly dollar adds ($000s)
A21: COST DRIVERS
A22: Hardware & Fulfillment COGS, % of (Jade + Store) revenue | C22: =Data_Actuals!D12/(Data_Actuals!D5+Data_Actuals!D7) -> 0.6013986 | D22: =Data_Actuals!E12/(Data_Actuals!E5+Data_Actuals!E7) -> 0.60628743 | E22: =Data_Actuals!F12/(Data_Actuals!F5+Data_Actuals!F7) -> 0.60365854 | F22: =Data_Actuals!G12/(Data_Actuals!G5+Data_Actuals!G7) -> 0.61290323 | G22: =Data_Actuals!H12/(Data_Actuals!H5+Data_Actuals!H7) -> 0.63047285 | H22: =(Data_Actuals!$D$12/(Data_Actuals!$D$5+Data_Actuals!$D$7)+Data_Actuals!$E$12/(Data_Actuals!$E$5+Data_Actuals!$E$7)+Data_Actuals!$F$12/(Data_Actuals!$F$5+Data_Actuals!$F$7)+Data_Actuals!$G$12/(Data_Actuals!$G$5+Data_Actuals!$G$7)+Data_Actuals!$H$12/(Data_Actuals!$H$5+Data_Actuals!$H$7))/5 -> 0.61094413 | I22: Average of 5 monthly ratios ~61%; excludes App subs (software margin). | K22: Hardware COGS as % of Jade + Store revenue
A23: Hosting & Infrastructure COGS, % of Enterprise revenue | C23: =Data_Actuals!D13/SUM(Data_Actuals!D8:D10) -> 0.14096916 | D23: =Data_Actuals!E13/SUM(Data_Actuals!E8:E10) -> 0.14442013 | E23: =Data_Actuals!F13/SUM(Data_Actuals!F8:F10) -> 0.13263158 | F23: =Data_Actuals!G13/SUM(Data_Actuals!G8:G10) -> 0.14197531 | G23: =Data_Actuals!H13/SUM(Data_Actuals!H8:H10) -> 0.13872832 | H23: =(Data_Actuals!$D$13/(Data_Actuals!$D$8+Data_Actuals!$D$9+Data_Actuals!$D$10)+Data_Actuals!$E$13/(Data_Actuals!$E$8+Data_Actuals!$E$9+Data_Actuals!$E$10)+Data_Actuals!$F$13/(Data_Actuals!$F$8+Data_Actuals!$F$9+Data_Actuals!$F$10)+Data_Actuals!$G$13/(Data_Actuals!$G$8+Data_Actuals!$G$9+Data_Actuals!$G$10)+Data_Actuals!$H$13/(Data_Actuals!$H$8+Data_Actuals!$H$9+Data_Actuals!$H$10))/5 -> 0.1397449 | I23: Average of 5 monthly ratios ~14%. | K23: Hosting COGS as % of Enterprise revenue
A24: Personnel R&D - monthly $ adds | C24: n/a | D24: =Data_Actuals!E14-Data_Actuals!D14 -> 30 | E24: =Data_Actuals!F14-Data_Actuals!E14 -> 30 | F24: =Data_Actuals!G14-Data_Actuals!F14 -> 30 | G24: =Data_Actuals!H14-Data_Actuals!G14 -> 35 | H24: =(Data_Actuals!$H$14-Data_Actuals!$D$14)/4 -> 31.25 | I24: Headcount-driven linear trend (+$31.3K/mo). | K24: Personnel R&D - monthly dollar adds ($000s)
A25: Personnel S&M - monthly $ adds | C25: n/a | D25: =Data_Actuals!E15-Data_Actuals!D15 -> 15 | E25: =Data_Actuals!F15-Data_Actuals!E15 -> 5 | F25: =Data_Actuals!G15-Data_Actuals!F15 -> 15 | G25: =Data_Actuals!H15-Data_Actuals!G15 -> 15 | H25: =(Data_Actuals!$H$15-Data_Actuals!$D$15)/4 -> 12.5 | I25: +$12.5K/mo. | K25: Personnel S&M - monthly dollar adds ($000s)
A26: Personnel G&A - monthly $ adds | C26: n/a | D26: =Data_Actuals!E16-Data_Actuals!D16 -> 5 | E26: =Data_Actuals!F16-Data_Actuals!E16 -> 5 | F26: =Data_Actuals!G16-Data_Actuals!F16 -> 10 | G26: =Data_Actuals!H16-Data_Actuals!G16 -> 10 | H26: =(Data_Actuals!$H$16-Data_Actuals!$D$16)/4 -> 7.5 | I26: +$7.5K/mo. | K26: Personnel G&A - monthly dollar adds ($000s)
A27: Cloud & Infrastructure - monthly run-rate Jun–Dec | C27: =Data_Actuals!D17 -> 285 | D27: =Data_Actuals!E17 -> 295 | E27: =Data_Actuals!F17 -> 340 | F27: =Data_Actuals!G17 -> 410 | G27: =Data_Actuals!H17 -> 480 | H27: 480 | I27: Judgment: hold the clean May run-rate ($480K) flat. GL total is $510K because of a $30K duplicate, but the reported P&L already excludes it; do not subtract it twice. This remains well above the $305K June budget and assumes containment, not remediation. Decision Log #5. | K27: Cloud & Infrastructure actual run-rate ($000s)
A28: All other OpEx lines, Jun–Dec | C28: =SUM(Data_Actuals!D18:D23) -> 573 | D28: =SUM(Data_Actuals!E18:E23) -> 553 | E28: =SUM(Data_Actuals!F18:F23) -> 729 | F28: =SUM(Data_Actuals!G18:G23) -> 711 | G28: =SUM(Data_Actuals!H18:H23) -> 847 | H28: Budget values | I28: Actuals track budget closely ex-Cloud; budget encodes real seasonality (e.g., $150K Bitcoin 2026 conference in June - the prepaid identified in GL_Recon releases there). | K28: Other OpEx actual total ($000s)
A30: BTC HOLDINGS DERIVATION (support for the 80 BTC input)
A31: Implied BTC held = monthly MTM ÷ Δ monthly avg price:
A32: Feb 2026 | H32: =Data_Actuals!$E$11*1000/(Data_KPIs!$D$5-Data_KPIs!$C$5) -> 70 | I32: Range ≈ 70–91 BTC. Position size is not disclosed in the pack; 80 BTC is the midpoint assumption and is a single input cell.
A33: Mar 2026 | H33: =Data_Actuals!$F$11*1000/(Data_KPIs!$E$5-Data_KPIs!$D$5) -> 84.615385
A34: Apr 2026 | H34: =Data_Actuals!$G$11*1000/(Data_KPIs!$F$5-Data_KPIs!$E$5) -> 75.555556
A35: May 2026 | H35: =Data_Actuals!$H$11*1000/(Data_KPIs!$G$5-Data_KPIs!$F$5) -> 90.625
A37: Materiality threshold for variance flags: greater of ±$50K and ±10% of budget (stated on BvA tab). | H37: 50
A38: Materiality % component | H38: 0.1

Sheet Forecast
A1: Driver-Based Forecast Jun–Dec 2026 - Base & Bear side by side ($000s)
A2: Both cases are driven ONLY by Inputs!H5 (BTC price) - bear applies the Inputs!H6 shock to that same cell. No BTC price is hardcoded on this tab. Flip Inputs!H5 and every number below recalculates. Bear isolates the BTC-price factor: operating volumes held at base to show pure price transmission (fees + treasury); volume elasticity would compound it further.
A4: SCENARIO SUMMARY (labeled cells the reviewer asked for)
A5: Base FY Operating Result | H5: =N39 -> -17359.332 | I5: FY2026 operating profit before treasury mark: Jan–May actuals + Jun–Dec forecast. Treasury-inclusive views on rows below the P&L.
A6: Bear FY Operating Result | H6: =W39 -> -19081.071
A7: Swing (Base − Bear) | H7: =H5-H6 -> 1721.739
A8: Memo: FY Net incl. treasury - Base | Bear | H8: =N41 -> -15059.332 | I8: =W41 -> -21101.071
A9: DRIVER GRID
A10: Driver | B10: Jan Actual | C10: Feb Actual | D10: Mar Actual | E10: Apr Actual | F10: May Actual | G10: Jun (Base) | H10: Jul (Base) | I10: Aug (Base) | J10: Sep (Base) | K10: Oct (Base) | L10: Nov (Base) | M10: Dec (Base) | N10: FY Base | O10: FY Check | P10: Jun (Bear) | Q10: Jul (Bear) | R10: Aug (Bear) | S10: Sep (Bear) | T10: Oct (Bear) | U10: Nov (Bear) | V10: Dec (Bear) | W10: FY Bear
A11: BTC price ($) | B11: =Data_KPIs!C5 -> 94000 | C11: =Data_KPIs!D5 -> 88000 | D11: =Data_KPIs!E5 -> 101000 | E11: =Data_KPIs!F5 -> 92000 | F11: =Data_KPIs!G5 -> 108000 | G11: =Inputs!$H$5 -> 108000 | H11: =G11 -> 108000 | I11: =H11 -> 108000 | J11: =I11 -> 108000 | K11: =J11 -> 108000 | L11: =K11 -> 108000 | M11: =L11 -> 108000 | P11: =Inputs!$H$5*(1+Inputs!$H$6) -> 54000 | Q11: =P11 -> 54000 | R11: =Q11 -> 54000 | S11: =R11 -> 54000 | T11: =S11 -> 54000 | U11: =T11 -> 54000 | V11: =U11 -> 54000
A12: Liquid pegged-in BTC | B12: =Data_KPIs!C9 -> 4200 | C12: =Data_KPIs!D9 -> 4350 | D12: =Data_KPIs!E9 -> 4480 | E12: =Data_KPIs!F9 -> 4620 | F12: =Data_KPIs!G9 -> 4810 | G12: =F12*(1+Inputs!$H$15) -> 4975.87 | H12: =G12*(1+Inputs!$H$15) -> 5147.4599 | I12: =H12*(1+Inputs!$H$15) -> 5324.9669 | J12: =I12*(1+Inputs!$H$15) -> 5508.5952 | K12: =J12*(1+Inputs!$H$15) -> 5698.5558 | L12: =K12*(1+Inputs!$H$15) -> 5895.0671 | M12: =L12*(1+Inputs!$H$15) -> 6098.355 | P12: =Data_KPIs!$G$9*(1+Inputs!$H$15) -> 4975.87 | Q12: =P12*(1+Inputs!$H$15) -> 5147.4599 | R12: =Q12*(1+Inputs!$H$15) -> 5324.9669 | S12: =R12*(1+Inputs!$H$15) -> 5508.5952 | T12: =S12*(1+Inputs!$H$15) -> 5698.5558 | U12: =T12*(1+Inputs!$H$15) -> 5895.0671 | V12: =U12*(1+Inputs!$H$15) -> 6098.355
A13: Jade units | B13: =Data_KPIs!C6 -> 7750 | C13: =Data_KPIs!D6 -> 7250 | D13: =Data_KPIs!E6 -> 8875 | E13: =Data_KPIs!F6 -> 6750 | F13: =Data_KPIs!G6 -> 6190 | G13: =F13*(1+Inputs!$H$11) -> 6190 | H13: =G13*(1+Inputs!$H$11) -> 6190 | I13: =H13*(1+Inputs!$H$11) -> 6190 | J13: =I13*(1+Inputs!$H$11) -> 6190 | K13: =J13*(1+Inputs!$H$11) -> 6190 | L13: =K13*(1+Inputs!$H$11) -> 6190 | M13: =L13*(1+Inputs!$H$11) -> 6190 | P13: =Data_KPIs!$G$6*(1+Inputs!$H$11) -> 6190 | Q13: =P13*(1+Inputs!$H$11) -> 6190 | R13: =Q13*(1+Inputs!$H$11) -> 6190 | S13: =R13*(1+Inputs!$H$11) -> 6190 | T13: =S13*(1+Inputs!$H$11) -> 6190 | U13: =T13*(1+Inputs!$H$11) -> 6190 | V13: =U13*(1+Inputs!$H$11) -> 6190
A15: P&L ($000s)
A16: Jade Hardware Wallet | B16: =Data_Actuals!D5 -> 620 | C16: =Data_Actuals!E5 -> 580 | D16: =Data_Actuals!F5 -> 710 | E16: =Data_Actuals!G5 -> 540 | F16: =Data_Actuals!H5 -> 495 | G16: =G13*Inputs!$H$12/1000 -> 495.2 | H16: =H13*Inputs!$H$12/1000 -> 495.2 | I16: =I13*Inputs!$H$12/1000 -> 495.2 | J16: =J13*Inputs!$H$12/1000 -> 495.2 | K16: =K13*Inputs!$H$12/1000 -> 495.2 | L16: =L13*Inputs!$H$12/1000 -> 495.2 | M16: =M13*Inputs!$H$12/1000 -> 495.2 | N16: =SUM(B16:M16) -> 6411.4 | O16: =N16-(SUM(Data_Actuals!$D$5:$H$5)+SUM(G16:M16)) -> 0 | P16: =P13*Inputs!$H$12/1000 -> 495.2 | Q16: =Q13*Inputs!$H$12/1000 -> 495.2 | R16: =R13*Inputs!$H$12/1000 -> 495.2 | S16: =S13*Inputs!$H$12/1000 -> 495.2 | T16: =T13*Inputs!$H$12/1000 -> 495.2 | U16: =U13*Inputs!$H$12/1000 -> 495.2 | V16: =V13*Inputs!$H$12/1000 -> 495.2 | W16: =SUM(Data_Actuals!$D$5:$H$5)+SUM(P16:V16) -> 6411.4
A17: Blockstream App & Subscriptions | B17: =Data_Actuals!D6 -> 210 | C17: =Data_Actuals!E6 -> 218 | D17: =Data_Actuals!F6 -> 225 | E17: =Data_Actuals!G6 -> 233 | F17: =Data_Actuals!H6 -> 240 | G17: =F17*(1+Inputs!$H$14) -> 248.14711 | H17: =G17*(1+Inputs!$H$14) -> 256.57079 | I17: =H17*(1+Inputs!$H$14) -> 265.28042 | J17: =I17*(1+Inputs!$H$14) -> 274.28571 | K17: =J17*(1+Inputs!$H$14) -> 283.5967 | L17: =K17*(1+Inputs!$H$14) -> 293.22376 | M17: =L17*(1+Inputs!$H$14) -> 303.17763 | N17: =SUM(B17:M17) -> 3050.2821 | O17: =N17-(SUM(Data_Actuals!$D$6:$H$6)+SUM(G17:M17)) -> 0 | P17: =F17*(1+Inputs!$H$14) -> 248.14711 | Q17: =P17*(1+Inputs!$H$14) -> 256.57079 | R17: =Q17*(1+Inputs!$H$14) -> 265.28042 | S17: =R17*(1+Inputs!$H$14) -> 274.28571 | T17: =S17*(1+Inputs!$H$14) -> 283.5967 | U17: =T17*(1+Inputs!$H$14) -> 293.22376 | V17: =U17*(1+Inputs!$H$14) -> 303.17763 | W17: =SUM(Data_Actuals!$D$6:$H$6)+SUM(P17:V17) -> 3050.2821
A18: Blockstream Store & Accessories | B18: =Data_Actuals!D7 -> 95 | C18: =Data_Actuals!E7 -> 88 | D18: =Data_Actuals!F7 -> 110 | E18: =Data_Actuals!G7 -> 80 | F18: =Data_Actuals!H7 -> 76 | G18: =G16*Inputs!$H$13 -> 75.499083 | H18: =H16*Inputs!$H$13 -> 75.499083 | I18: =I16*Inputs!$H$13 -> 75.499083 | J18: =J16*Inputs!$H$13 -> 75.499083 | K18: =K16*Inputs!$H$13 -> 75.499083 | L18: =L16*Inputs!$H$13 -> 75.499083 | M18: =M16*Inputs!$H$13 -> 75.499083 | N18: =SUM(B18:M18) -> 977.49358 | O18: =N18-(SUM(Data_Actuals!$D$7:$H$7)+SUM(G18:M18)) -> 0 | P18: =P16*Inputs!$H$13 -> 75.499083 | Q18: =Q16*Inputs!$H$13 -> 75.499083 | R18: =R16*Inputs!$H$13 -> 75.499083 | S18: =S16*Inputs!$H$13 -> 75.499083 | T18: =T16*Inputs!$H$13 -> 75.499083 | U18: =U16*Inputs!$H$13 -> 75.499083 | V18: =V16*Inputs!$H$13 -> 75.499083 | W18: =SUM(Data_Actuals!$D$7:$H$7)+SUM(P18:V18) -> 977.49358
A19: A&H Revenue | B19: =SUM(B16:B18) -> 925 | C19: =SUM(C16:C18) -> 886 | D19: =SUM(D16:D18) -> 1045 | E19: =SUM(E16:E18) -> 853 | F19: =SUM(F16:F18) -> 811 | G19: =SUM(G16:G18) -> 818.8462 | H19: =SUM(H16:H18) -> 827.26988 | I19: =SUM(I16:I18) -> 835.97951 | ... M19: =SUM(M16:M18) -> 873.87671 | N19: =SUM(B19:M19) -> 10439.176 | O19: =N19-SUM(N16:N18) -> 0 | P19: =SUM(P16:P18) -> 818.8462 | Q19: =SUM(Q16:Q18) -> 827.26988 | R19: =SUM(R16:R18) -> 835.97951 | S19: =SUM(S16:S18) -> 844.9848 | T19: =SUM(T16:T18) -> 854.29578 | U19: =SUM(U16:U18) -> 863.92285 | V19: =SUM(V16:V18) -> 873.87671 | W19: =SUM(W16:W18) -> 10439.176
A20: Liquid Network Fees | B20: =Data_Actuals!D8 -> 380 | C20: =Data_Actuals!E8 -> 350 | D20: =Data_Actuals!F8 -> 445 | E20: =Data_Actuals!G8 -> 405 | F20: =Data_Actuals!H8 -> 510 | G20: =G12*G11/1000*Inputs!$H$16 -> 515.35001 | H20: =H12*H11/1000*Inputs!$H$16 -> 533.12155 | I20: =I12*I11/1000*Inputs!$H$16 -> 551.50593 | J20: =J12*J11/1000*Inputs!$H$16 -> 570.52428 | K20: =K12*K11/1000*Inputs!$H$16 -> 590.19847 | L20: =L12*L11/1000*Inputs!$H$16 -> 610.55111 | M20: =M12*M11/1000*Inputs!$H$16 -> 631.6056 | N20: =SUM(B20:M20) -> 6092.8569 | O20: =N20-(SUM(Data_Actuals!$D$8:$H$8)+SUM(G20:M20)) -> 0 | P20: =P12*P11/1000*Inputs!$H$16 -> 257.67501 | Q20: =Q12*Q11/1000*Inputs!$H$16 -> 266.56077 | R20: =R12*R11/1000*Inputs!$H$16 -> 275.75296 | S20: =S12*S11/1000*Inputs!$H$16 -> 285.26214 | T20: =T12*T11/1000*Inputs!$H$16 -> 295.09923 | U20: =U12*U11/1000*Inputs!$H$16 -> 305.27555 | V20: =V12*V11/1000*Inputs!$H$16 -> 315.8028 | W20: =SUM(Data_Actuals!$D$8:$H$8)+SUM(P20:V20) -> 4091.4285
A21: Blockstream AMP (SaaS) | B21: =Data_Actuals!D9 -> 1250 | C21: =Data_Actuals!E9 -> 1280 | D21: =Data_Actuals!F9 -> 1310 | E21: =Data_Actuals!G9 -> 1345 | F21: =Data_Actuals!H9 -> 1380 | G21: =F21+Inputs!$H$18 -> 1412.5 | H21: =G21+Inputs!$H$18 -> 1445 | I21: =H21+Inputs!$H$18 -> 1477.5 | J21: =I21+Inputs!$H$18 -> 1510 | K21: =J21+Inputs!$H$18 -> 1542.5 | L21: =K21+Inputs!$H$18 -> 1575 | M21: =L21+Inputs!$H$18 -> 1607.5 | N21: =SUM(B21:M21) -> 17135 | O21: =N21-(SUM(Data_Actuals!$D$9:$H$9)+SUM(G21:M21)) -> 0 | P21: =F21+Inputs!$H$18 -> 1412.5 | Q21: =P21+Inputs!$H$18 -> 1445 | R21: =Q21+Inputs!$H$18 -> 1477.5 | S21: =R21+Inputs!$H$18 -> 1510 | T21: =S21+Inputs!$H$18 -> 1542.5 | U21: =T21+Inputs!$H$18 -> 1575 | V21: =U21+Inputs!$H$18 -> 1607.5 | W21: =SUM(Data_Actuals!$D$9:$H$9)+SUM(P21:V21) -> 17135
A22: Enterprise Infrastructure & Licensing | B22: =Data_Actuals!D10 -> 640 | C22: =Data_Actuals!E10 -> 655 | D22: =Data_Actuals!F10 -> 620 | E22: =Data_Actuals!G10 -> 680 | F22: =Data_Actuals!H10 -> 705 | G22: =F22+Inputs!$H$19 -> 721.25 | H22: =G22+Inputs!$H$19 -> 737.5 | I22: =H22+Inputs!$H$19 -> 753.75 | J22: =I22+Inputs!$H$19 -> 770 | K22: =J22+Inputs!$H$19 -> 786.25 | L22: =K22+Inputs!$H$19 -> 802.5 | M22: =L22+Inputs!$H$19 -> 818.75 | N22: =SUM(B22:M22) -> 8690 | O22: =N22-(SUM(Data_Actuals!$D$10:$H$10)+SUM(G22:M22)) -> 0 | P22: =F22+Inputs!$H$19 -> 721.25 | Q22: =P22+Inputs!$H$19 -> 737.5 | R22: =Q22+Inputs!$H$19 -> 753.75 | S22: =R22+Inputs!$H$19 -> 770 | T22: =S22+Inputs!$H$19 -> 786.25 | U22: =T22+Inputs!$H$19 -> 802.5 | V22: =U22+Inputs!$H$19 -> 818.75 | W22: =SUM(Data_Actuals!$D$10:$H$10)+SUM(P22:V22) -> 8690
A23: Enterprise Revenue | B23: =SUM(B20:B22) -> 2270 | C23: =SUM(C20:C22) -> 2285 | D23: =SUM(D20:D22) -> 2375 | E23: =SUM(E20:E22) -> 2430 | F23: =SUM(F20:F22) -> 2595 | G23: =SUM(G20:G22) -> 2649.1 | H23: =SUM(H20:H22) -> 2715.6215 | I23: =SUM(I20:I22) -> 2782.7559 | ... M23: =SUM(M20:M22) -> 3057.8556 | N23: =SUM(B23:M23) -> 31917.857 | O23: =N23-SUM(N20:N22) -> 0 | P23: =SUM(P20:P22) -> 2391.425 | Q23: =SUM(Q20:Q22) -> 2449.0608 | R23: =SUM(R20:R22) -> 2507.003 | S23: =SUM(S20:S22) -> 2565.2621 | T23: =SUM(T20:T22) -> 2623.8492 | U23: =SUM(U20:U22) -> 2682.7756 | V23: =SUM(V20:V22) -> 2742.0528 | W23: =SUM(W20:W22) -> 29916.428
A24: Total Revenue | B24: =B19+B23 -> 3195 | C24: =C19+C23 -> 3171 | D24: =D19+D23 -> 3420 | E24: =E19+E23 -> 3283 | F24: =F19+F23 -> 3406 | G24: =G19+G23 -> 3467.9462 | H24: =H19+H23 -> 3542.8914 | I24: =I19+I23 -> 3618.7354 | ... M24: =M19+M23 -> 3931.7323 | N24: =SUM(B24:M24) -> 42357.033 | O24: =N24-(N19+N23) -> 0 | P24: =P19+P23 -> 3210.2712 | Q24: =Q19+Q23 -> 3276.3307 | R24: =R19+R23 -> 3342.9825 | S24: =S19+S23 -> 3410.2469 | T24: =T19+T23 -> 3478.145 | U24: =U19+U23 -> 3546.6984 | V24: =V19+V23 -> 3615.9295 | W24: =W19+W23 -> 40355.604
A25: Hardware & Fulfillment COGS | B25: =Data_Actuals!D12 -> 430 | C25: =Data_Actuals!E12 -> 405 | D25: =Data_Actuals!F12 -> 495 | E25: =Data_Actuals!G12 -> 380 | F25: =Data_Actuals!H12 -> 360 | G25: =(G16+G18)*Inputs!$H$22 -> 348.66525 | H25: =(H16+H18)*Inputs!$H$22 -> 348.66525 | I25: =(I16+I18)*Inputs!$H$22 -> 348.66525 | J25: =(J16+J18)*Inputs!$H$22 -> 348.66525 | K25: =(K16+K18)*Inputs!$H$22 -> 348.66525 | L25: =(L16+L18)*Inputs!$H$22 -> 348.66525 | M25: =(M16+M18)*Inputs!$H$22 -> 348.66525 | N25: =SUM(B25:M25) -> 4510.6568 | O25: =N25-(SUM(Data_Actuals!$D$12:$H$12)+SUM(G25:M25)) -> 0 | P25: =(P16+P18)*Inputs!$H$22 -> 348.66525 | Q25: =(Q16+Q18)*Inputs!$H$22 -> 348.66525 | R25: =(R16+R18)*Inputs!$H$22 -> 348.66525 | S25: =(S16+S18)*Inputs!$H$22 -> 348.66525 | T25: =(T16+T18)*Inputs!$H$22 -> 348.66525 | U25: =(U16+U18)*Inputs!$H$22 -> 348.66525 | V25: =(V16+V18)*Inputs!$H$22 -> 348.66525 | W25: =SUM(Data_Actuals!$D$12:$H$12)+SUM(P25:V25) -> 4510.6568
A26: Hosting & Infrastructure COGS | B26: =Data_Actuals!D13 -> 320 | C26: =Data_Actuals!E13 -> 330 | D26: =Data_Actuals!F13 -> 315 | E26: =Data_Actuals!G13 -> 345 | F26: =Data_Actuals!H13 -> 360 | G26: =G23*Inputs!$H$23 -> 370.19822 | H26: =H23*Inputs!$H$23 -> 379.49426 | I26: =I23*Inputs!$H$23 -> 388.87595 | J26: =J23*Inputs!$H$23 -> 398.34623 | K26: =K23*Inputs!$H$23 -> 407.90816 | L26: =L23*Inputs!$H$23 -> 417.56491 | M26: =M23*Inputs!$H$23 -> 427.31973 | N26: =SUM(B26:M26) -> 4459.7075 | O26: =N26-(SUM(Data_Actuals!$D$13:$H$13)+SUM(G26:M26)) -> 0 | P26: =P23*Inputs!$H$23 -> 334.18945 | Q26: =Q23*Inputs!$H$23 -> 342.24376 | R26: =R23*Inputs!$H$23 -> 350.34088 | S26: =S23*Inputs!$H$23 -> 358.4823 | T26: =T23*Inputs!$H$23 -> 366.66955 | U26: =U23*Inputs!$H$23 -> 374.9042 | V26: =V23*Inputs!$H$23 -> 383.1879 | W26: =SUM(Data_Actuals!$D$13:$H$13)+SUM(P26:V26) -> 4180.018
A27: Gross Profit | B27: =B24-B25-B26 -> 2445 | C27: =C24-C25-C26 -> 2436 | D27: =D24-D25-D26 -> 2610 | E27: =E24-E25-E26 -> 2558 | F27: =F24-F25-F26 -> 2686 | G27: =G24-G25-G26 -> 2749.0827 | H27: =H24-H25-H26 -> 2814.7319 | I27: =I24-I25-I26 -> 2881.1942 | ... M27: =M24-M25-M26 -> 3155.7473 | N27: =SUM(B27:M27) -> 33386.668 | O27: =N27-(N24-N25-N26) -> 0 | P27: =P24-P25-P26 -> 2527.4165 | Q27: =Q24-Q25-Q26 -> 2585.4216 | R27: =R24-R25-R26 -> 2643.9763 | S27: =S24-S25-S26 -> 2703.0994 | T27: =T24-T25-T26 -> 2762.8102 | U27: =U24-U25-U26 -> 2823.1289 | V27: =V24-V25-V26 -> 2884.0764 | W27: =W24-W25-W26 -> 31664.929
A28: Personnel - R&D / Engineering | B28: =Data_Actuals!D14 -> 1850 | C28: =Data_Actuals!E14 -> 1880 | D28: =Data_Actuals!F14 -> 1910 | E28: =Data_Actuals!G14 -> 1940 | F28: =Data_Actuals!H14 -> 1975 | G28: =F28+Inputs!$H$24 -> 2006.25 | H28: =G28+Inputs!$H$24 -> 2037.5 | I28: =H28+Inputs!$H$24 -> 2068.75 | J28: =I28+Inputs!$H$24 -> 2100 | K28: =J28+Inputs!$H$24 -> 2131.25 | L28: =K28+Inputs!$H$24 -> 2162.5 | M28: =L28+Inputs!$H$24 -> 2193.75 | N28: =SUM(B28:M28) -> 24255 | O28: =N28-(SUM(Data_Actuals!$D$14:$H$14)+SUM(G28:M28)) -> 0 | P28: =F28+Inputs!$H$24 -> 2006.25 | Q28: =P28+Inputs!$H$24 -> 2037.5 | R28: =Q28+Inputs!$H$24 -> 2068.75 | S28: =R28+Inputs!$H$24 -> 2100 | T28: =S28+Inputs!$H$24 -> 2131.25 | U28: =T28+Inputs!$H$24 -> 2162.5 | V28: =U28+Inputs!$H$24 -> 2193.75 | W28: =SUM(Data_Actuals!$D$14:$H$14)+SUM(P28:V28) -> 24255
A29: Personnel - Sales & Marketing | B29: =Data_Actuals!D15 -> 540 | C29: =Data_Actuals!E15 -> 555 | D29: =Data_Actuals!F15 -> 560 | E29: =Data_Actuals!G15 -> 575 | F29: =Data_Actuals!H15 -> 590 | G29: =F29+Inputs!$H$25 -> 602.5 | H29: =G29+Inputs!$H$25 -> 615 | I29: =H29+Inputs!$H$25 -> 627.5 | J29: =I29+Inputs!$H$25 -> 640 | K29: =J29+Inputs!$H$25 -> 652.5 | L29: =K29+Inputs!$H$25 -> 665 | M29: =L29+Inputs!$H$25 -> 677.5 | N29: =SUM(B29:M29) -> 7300 | O29: =N29-(SUM(Data_Actuals!$D$15:$H$15)+SUM(G29:M29)) -> 0 | P29: =F29+Inputs!$H$25 -> 602.5 | Q29: =P29+Inputs!$H$25 -> 615 | R29: =Q29+Inputs!$H$25 -> 627.5 | S29: =R29+Inputs!$H$25 -> 640 | T29: =S29+Inputs!$H$25 -> 652.5 | U29: =T29+Inputs!$H$25 -> 665 | V29: =U29+Inputs!$H$25 -> 677.5 | W29: =SUM(Data_Actuals!$D$15:$H$15)+SUM(P29:V29) -> 7300
A30: Personnel - G&A | B30: =Data_Actuals!D16 -> 420 | C30: =Data_Actuals!E16 -> 425 | D30: =Data_Actuals!F16 -> 430 | E30: =Data_Actuals!G16 -> 440 | F30: =Data_Actuals!H16 -> 450 | G30: =F30+Inputs!$H$26 -> 457.5 | H30: =G30+Inputs!$H$26 -> 465 | I30: =H30+Inputs!$H$26 -> 472.5 | J30: =I30+Inputs!$H$26 -> 480 | K30: =J30+Inputs!$H$26 -> 487.5 | L30: =K30+Inputs!$H$26 -> 495 | M30: =L30+Inputs!$H$26 -> 502.5 | N30: =SUM(B30:M30) -> 5525 | O30: =N30-(SUM(Data_Actuals!$D$16:$H$16)+SUM(G30:M30)) -> 0 | P30: =F30+Inputs!$H$26 -> 457.5 | Q30: =P30+Inputs!$H$26 -> 465 | R30: =Q30+Inputs!$H$26 -> 472.5 | S30: =R30+Inputs!$H$26 -> 480 | T30: =S30+Inputs!$H$26 -> 487.5 | U30: =T30+Inputs!$H$26 -> 495 | V30: =U30+Inputs!$H$26 -> 502.5 | W30: =SUM(Data_Actuals!$D$16:$H$16)+SUM(P30:V30) -> 5525
A31: Cloud & Infrastructure | B31: =Data_Actuals!D17 -> 285 | C31: =Data_Actuals!E17 -> 295 | D31: =Data_Actuals!F17 -> 340 | E31: =Data_Actuals!G17 -> 410 | F31: =Data_Actuals!H17 -> 480 | G31: =Inputs!$H$27 -> 480 | H31: =Inputs!$H$27 -> 480 | I31: =Inputs!$H$27 -> 480 | J31: =Inputs!$H$27 -> 480 | K31: =Inputs!$H$27 -> 480 | L31: =Inputs!$H$27 -> 480 | M31: =Inputs!$H$27 -> 480 | N31: =SUM(B31:M31) -> 5170 | O31: =N31-(SUM(Data_Actuals!$D$17:$H$17)+SUM(G31:M31)) -> 0 | P31: =Inputs!$H$27 -> 480 | Q31: =Inputs!$H$27 -> 480 | R31: =Inputs!$H$27 -> 480 | S31: =Inputs!$H$27 -> 480 | T31: =Inputs!$H$27 -> 480 | U31: =Inputs!$H$27 -> 480 | V31: =Inputs!$H$27 -> 480 | W31: =SUM(Data_Actuals!$D$17:$H$17)+SUM(P31:V31) -> 5170
A32: Marketing Programs | B32: =Data_Actuals!D18 -> 180 | C32: =Data_Actuals!E18 -> 165 | D32: =Data_Actuals!F18 -> 220 | E32: =Data_Actuals!G18 -> 195 | F32: =Data_Actuals!H18 -> 240 | G32: =Data_Budget!$I$18 -> 225 | H32: =Data_Budget!$J$18 -> 225 | I32: =Data_Budget!$K$18 -> 225 | J32: =Data_Budget!$L$18 -> 250 | K32: =Data_Budget!$M$18 -> 250 | L32: =Data_Budget!$N$18 -> 250 | M32: =Data_Budget!$O$18 -> 275 | N32: =SUM(B32:M32) -> 2700 | O32: =N32-(SUM(Data_Actuals!$D$18:$H$18)+SUM(G32:M32)) -> 0 | P32: =Data_Budget!$I$18 -> 225 | Q32: =Data_Budget!$J$18 -> 225 | R32: =Data_Budget!$K$18 -> 225 | S32: =Data_Budget!$L$18 -> 250 | T32: =Data_Budget!$M$18 -> 250 | U32: =Data_Budget!$N$18 -> 250 | V32: =Data_Budget!$O$18 -> 275 | W32: =SUM(Data_Actuals!$D$18:$H$18)+SUM(P32:V32) -> 2700
A33: Travel & Events | B33: =Data_Actuals!D19 -> 65 | C33: =Data_Actuals!E19 -> 48 | D33: =Data_Actuals!F19 -> 120 | E33: =Data_Actuals!G19 -> 95 | F33: =Data_Actuals!H19 -> 175 | G33: =Data_Budget!$I$19 -> 150 | H33: =Data_Budget!$J$19 -> 80 | I33: =Data_Budget!$K$19 -> 80 | J33: =Data_Budget!$L$19 -> 90 | K33: =Data_Budget!$M$19 -> 80 | L33: =Data_Budget!$N$19 -> 80 | M33: =Data_Budget!$O$19 -> 100 | N33: =SUM(B33:M33) -> 1163 | O33: =N33-(SUM(Data_Actuals!$D$19:$H$19)+SUM(G33:M33)) -> 0 | P33: =Data_Budget!$I$19 -> 150 | Q33: =Data_Budget!$J$19 -> 80 | R33: =Data_Budget!$K$19 -> 80 | S33: =Data_Budget!$L$19 -> 90 | T33: =Data_Budget!$M$19 -> 80 | U33: =Data_Budget!$N$19 -> 80 | V33: =Data_Budget!$O$19 -> 100 | W33: =SUM(Data_Actuals!$D$19:$H$19)+SUM(P33:V33) -> 1163
A34: Professional Services | B34: =Data_Actuals!D20 -> 95 | C34: =Data_Actuals!E20 -> 110 | D34: =Data_Actuals!F20 -> 140 | E34: =Data_Actuals!G20 -> 180 | F34: =Data_Actuals!H20 -> 165 | G34: =Data_Budget!$I$20 -> 140 | H34: =Data_Budget!$J$20 -> 120 | I34: =Data_Budget!$K$20 -> 120 | J34: =Data_Budget!$L$20 -> 140 | K34: =Data_Budget!$M$20 -> 120 | L34: =Data_Budget!$N$20 -> 120 | M34: =Data_Budget!$O$20 -> 160 | N34: =SUM(B34:M34) -> 1610 | O34: =N34-(SUM(Data_Actuals!$D$20:$H$20)+SUM(G34:M34)) -> 0 | P34: =Data_Budget!$I$20 -> 140 | Q34: =Data_Budget!$J$20 -> 120 | R34: =Data_Budget!$K$20 -> 120 | S34: =Data_Budget!$L$20 -> 140 | T34: =Data_Budget!$M$20 -> 120 | U34: =Data_Budget!$N$20 -> 120 | V34: =Data_Budget!$O$20 -> 160 | W34: =SUM(Data_Actuals!$D$20:$H$20)+SUM(P34:V34) -> 1610
A35: Software & Tools | B35: =Data_Actuals!D21 -> 78 | C35: =Data_Actuals!E21 -> 82 | D35: =Data_Actuals!F21 -> 85 | E35: =Data_Actuals!G21 -> 88 | F35: =Data_Actuals!H21 -> 92 | G35: =Data_Budget!$I$21 -> 84 | H35: =Data_Budget!$J$21 -> 86 | I35: =Data_Budget!$K$21 -> 86 | J35: =Data_Budget!$L$21 -> 88 | K35: =Data_Budget!$M$21 -> 88 | L35: =Data_Budget!$N$21 -> 90 | M35: =Data_Budget!$O$21 -> 90 | N35: =SUM(B35:M35) -> 1037 | O35: =N35-(SUM(Data_Actuals!$D$21:$H$21)+SUM(G35:M35)) -> 0 | P35: =Data_Budget!$I$21 -> 84 | Q35: =Data_Budget!$J$21 -> 86 | R35: =Data_Budget!$K$21 -> 86 | S35: =Data_Budget!$L$21 -> 88 | T35: =Data_Budget!$M$21 -> 88 | U35: =Data_Budget!$N$21 -> 90 | V35: =Data_Budget!$O$21 -> 90 | W35: =SUM(Data_Actuals!$D$21:$H$21)+SUM(P35:V35) -> 1037
A36: Facilities | B36: =Data_Actuals!D22 -> 110 | C36: =Data_Actuals!E22 -> 110 | D36: =Data_Actuals!F22 -> 112 | E36: =Data_Actuals!G22 -> 112 | F36: =Data_Actuals!H22 -> 115 | G36: =Data_Budget!$I$22 -> 112 | H36: =Data_Budget!$J$22 -> 115 | I36: =Data_Budget!$K$22 -> 115 | J36: =Data_Budget!$L$22 -> 115 | K36: =Data_Budget!$M$22 -> 118 | L36: =Data_Budget!$N$22 -> 118 | M36: =Data_Budget!$O$22 -> 118 | N36: =SUM(B36:M36) -> 1370 | O36: =N36-(SUM(Data_Actuals!$D$22:$H$22)+SUM(G36:M36)) -> 0 | P36: =Data_Budget!$I$22 -> 112 | Q36: =Data_Budget!$J$22 -> 115 | R36: =Data_Budget!$K$22 -> 115 | S36: =Data_Budget!$L$22 -> 115 | T36: =Data_Budget!$M$22 -> 118 | U36: =Data_Budget!$N$22 -> 118 | V36: =Data_Budget!$O$22 -> 118 | W36: =SUM(Data_Actuals!$D$22:$H$22)+SUM(P36:V36) -> 1370
A37: Other OpEx | B37: =Data_Actuals!D23 -> 45 | C37: =Data_Actuals!E23 -> 38 | D37: =Data_Actuals!F23 -> 52 | E37: =Data_Actuals!G23 -> 41 | F37: =Data_Actuals!H23 -> 60 | G37: =Data_Budget!$I$23 -> 50 | H37: =Data_Budget!$J$23 -> 52 | I37: =Data_Budget!$K$23 -> 52 | J37: =Data_Budget!$L$23 -> 55 | K37: =Data_Budget!$M$23 -> 55 | L37: =Data_Budget!$N$23 -> 58 | M37: =Data_Budget!$O$23 -> 58 | N37: =SUM(B37:M37) -> 616 | O37: =N37-(SUM(Data_Actuals!$D$23:$H$23)+SUM(G37:M37)) -> 0 | P37: =Data_Budget!$I$23 -> 50 | Q37: =Data_Budget!$J$23 -> 52 | R37: =Data_Budget!$K$23 -> 52 | S37: =Data_Budget!$L$23 -> 55 | T37: =Data_Budget!$M$23 -> 55 | U37: =Data_Budget!$N$23 -> 58 | V37: =Data_Budget!$O$23 -> 58 | W37: =SUM(Data_Actuals!$D$23:$H$23)+SUM(P37:V37) -> 616
A38: Total OpEx | B38: =SUM(B28:B37) -> 3668 | C38: =SUM(C28:C37) -> 3708 | D38: =SUM(D28:D37) -> 3969 | E38: =SUM(E28:E37) -> 4076 | F38: =SUM(F28:F37) -> 4342 | G38: =SUM(G28:G37) -> 4307.25 | H38: =SUM(H28:H37) -> 4275.5 | I38: =SUM(I28:I37) -> 4326.75 | ... M38: =SUM(M28:M37) -> 4654.75 | N38: =SUM(B38:M38) -> 50746 | O38: =N38-SUM(N28:N37) -> 0 | P38: =SUM(P28:P37) -> 4307.25 | Q38: =SUM(Q28:Q37) -> 4275.5 | R38: =SUM(R28:R37) -> 4326.75 | S38: =SUM(S28:S37) -> 4438 | T38: =SUM(T28:T37) -> 4462.25 | U38: =SUM(U28:U37) -> 4518.5 | V38: =SUM(V28:V37) -> 4654.75 | W38: =SUM(W28:W37) -> 50746
A39: Operating Profit (before treasury) | B39: =B27-B38 -> -1223 | C39: =C27-C38 -> -1272 | D39: =D27-D38 -> -1359 | E39: =E27-E38 -> -1518 | F39: =F27-F38 -> -1656 | G39: =G27-G38 -> -1558.1673 | H39: =H27-H38 -> -1460.7681 | I39: =I27-I38 -> -1445.5558 | ... M39: =M27-M38 -> -1499.0027 | N39: =SUM(B39:M39) -> -17359.332 | O39: =N39-(N27-N38) -> 0 | P39: =P27-P38 -> -1779.8335 | Q39: =Q27-Q38 -> -1690.0784 | R39: =R27-R38 -> -1682.7737 | S39: =S27-S38 -> -1734.9006 | T39: =T27-T38 -> -1699.4398 | U39: =U27-U38 -> -1695.3711 | V39: =V27-V38 -> -1770.6736 | W39: =W27-W38 -> -19081.071
A40: BTC Treasury Mark-to-Market | B40: =Data_Actuals!D11 -> 850 | C40: =Data_Actuals!E11 -> -420 | D40: =Data_Actuals!F11 -> 1100 | E40: =Data_Actuals!G11 -> -680 | F40: =Data_Actuals!H11 -> 1450 | G40: =Inputs!$H$8*(G11-Data_KPIs!$G$5)/1000 -> 0 | H40: =0 -> 0 | I40: =0 -> 0 | J40: =0 -> 0 | K40: =0 -> 0 | L40: =0 -> 0 | M40: =0 -> 0 | N40: =SUM(B40:M40) -> 2300 | O40: =N40-(SUM(Data_Actuals!$D$11:$H$11)+SUM(G40:M40)) -> 0 | P40: =Inputs!$H$8*(P11-Data_KPIs!$G$5)/1000 -> -4320 | Q40: =0 -> 0 | R40: =0 -> 0 | S40: =0 -> 0 | T40: =0 -> 0 | U40: =0 -> 0 | V40: =0 -> 0 | W40: =SUM(Data_Actuals!$D$11:$H$11)+SUM(P40:V40) -> -2020
A41: Net Result incl. treasury | B41: =B39+B40 -> -373 | C41: =C39+C40 -> -1692 | D41: =D39+D40 -> -259 | E41: =E39+E40 -> -2198 | F41: =F39+F40 -> -206 | G41: =G39+G40 -> -1558.1673 | H41: =H39+H40 -> -1460.7681 | I41: =I39+I40 -> -1445.5558 | ... M41: =M39+M40 -> -1499.0027 | N41: =SUM(B41:M41) -> -15059.332 | O41: =N41-(N39+N40) -> 0 | P41: =P39+P40 -> -6099.8335 | Q41: =Q39+Q40 -> -1690.0784 | R41: =R39+R40 -> -1682.7737 | S41: =S39+S40 -> -1734.9006 | T41: =T39+T40 -> -1699.4398 | U41: =U39+U40 -> -1695.3711 | V41: =V39+V40 -> -1770.6736 | W41: =W39+W40 -> -21101.071
A43: Treasury mark: recognized in June as (scenario price − May avg price) × holdings, then held flat (flat price path ⇒ no further marks). Jan–May actual marks are included in the FY columns.

Sheet BvA
A1: Segment P&L - May 2026 and YTD (Jan–May) Actual vs Budget ($000s)
A2: Materiality flag = |$ var| ≥ $50K AND |% var| ≥ 10% of budget (Inputs!H37:H38). Costs: actual < budget is favorable. Corporate OpEx is deliberately NOT allocated to segments - segments are shown at contribution margin (what their leaders control); see Alloc_View for the fully-allocated sensitivity. Decision Log #1.
A4: Line ($000s) | B4: May Actual | C4: May Budget | D4: $ Var | E4: % Var | F4: Assessment | G4: YTD Actual | H4: YTD Budget | I4: $ Var | J4: % Var | K4: Assessment
A5: APP & HARDWARE
A6: Jade Hardware Wallet | B6: =Data_Actuals!$H$5 -> 495 | C6: =Data_Budget!$H$5 -> 660 | D6: =B6-C6 -> -165 | E6: =IF(C6=0,"n/m",D6/ABS(C6)) -> -0.25 | F6: =IF(E6="n/m","n/m - see note",IF(AND(ABS(D6)>=Inputs!$H$37,ABS(E6)>=Inputs!$H$38),IF(D6>0,"Favorable - material","UNFAVORABLE - material"),"")) -> UNFAVORABLE - material | G6: =SUM(Data_Actuals!$D$5:$H$5) -> 2945 | H6: =SUM(Data_Budget!$D$5:$H$5) -> 3120 | I6: =G6-H6 -> -175 | J6: =IF(H6=0,"n/m",I6/ABS(H6)) -> -0.056089744 | K6: =IF(J6="n/m","n/m - see note",IF(AND(ABS(I6)>=Inputs!$H$37,ABS(J6)>=Inputs!$H$38),IF(I6>0,"Favorable - material","UNFAVORABLE - material"),""))
A7: Blockstream App & Subscriptions | B7: =Data_Actuals!$H$6 -> 240 | C7: =Data_Budget!$H$6 -> 233 | D7: =B7-C7 -> 7 | E7: =IF(C7=0,"n/m",D7/ABS(C7)) -> 0.030042918 | F7: =IF(E7="n/m","n/m - see note",IF(AND(ABS(D7)>=Inputs!$H$37,ABS(E7)>=Inputs!$H$38),IF(D7>0,"Favorable - material","UNFAVORABLE - material"),"")) | G7: =SUM(Data_Actuals!$D$6:$H$6) -> 1126 | H7: =SUM(Data_Budget!$D$6:$H$6) -> 1095 | I7: =G7-H7 -> 31 | J7: =IF(H7=0,"n/m",I7/ABS(H7)) -> 0.028310502 | K7: =IF(J7="n/m","n/m - see note",IF(AND(ABS(I7)>=Inputs!$H$37,ABS(J7)>=Inputs!$H$38),IF(I7>0,"Favorable - material","UNFAVORABLE - material"),""))
A8: Blockstream Store & Accessories | B8: =Data_Actuals!$H$7 -> 76 | C8: =Data_Budget!$H$7 -> 100 | D8: =B8-C8 -> -24 | E8: =IF(C8=0,"n/m",D8/ABS(C8)) -> -0.24 | F8: =IF(E8="n/m","n/m - see note",IF(AND(ABS(D8)>=Inputs!$H$37,ABS(E8)>=Inputs!$H$38),IF(D8>0,"Favorable - material","UNFAVORABLE - material"),"")) | G8: =SUM(Data_Actuals!$D$7:$H$7) -> 449 | H8: =SUM(Data_Budget!$D$7:$H$7) -> 470 | I8: =G8-H8 -> -21 | J8: =IF(H8=0,"n/m",I8/ABS(H8)) -> -0.044680851 | K8: =IF(J8="n/m","n/m - see note",IF(AND(ABS(I8)>=Inputs!$H$37,ABS(J8)>=Inputs!$H$38),IF(I8>0,"Favorable - material","UNFAVORABLE - material"),""))
A9: A&H Revenue | B9: =SUM(B6:B8) -> 811 | C9: =SUM(C6:C8) -> 993 | D9: =B9-C9 -> -182 | E9: =IF(C9=0,"n/m",D9/ABS(C9)) -> -0.18328298 | F9: =IF(E9="n/m","n/m - see note",IF(AND(ABS(D9)>=Inputs!$H$37,ABS(E9)>=Inputs!$H$38),IF(D9>0,"Favorable - material","UNFAVORABLE - material"),"")) -> UNFAVORABLE - material | G9: =SUM(G6:G8) -> 4520 | H9: =SUM(H6:H8) -> 4685 | I9: =G9-H9 -> -165 | J9: =IF(H9=0,"n/m",I9/ABS(H9)) -> -0.035218783 | K9: =IF(J9="n/m","n/m - see note",IF(AND(ABS(I9)>=Inputs!$H$37,ABS(J9)>=Inputs!$H$38),IF(I9>0,"Favorable - material","UNFAVORABLE - material"),""))
A10: Hardware & Fulfillment | B10: =Data_Actuals!$H$12 -> 360 | C10: =Data_Budget!$H$12 -> 455 | D10: =B10-C10 -> -95 | E10: =IF(C10=0,"n/m",D10/ABS(C10)) -> -0.20879121 | F10: =IF(E10="n/m","n/m - see note",IF(AND(ABS(D10)>=Inputs!$H$37,ABS(E10)>=Inputs!$H$38),IF(D10<0,"Favorable - material","UNFAVORABLE - material"),"")) -> Favorable - material | G10: =SUM(Data_Actuals!$D$12:$H$12) -> 2070 | H10: =SUM(Data_Budget!$D$12:$H$12) -> 2140 | I10: =G10-H10 -> -70 | J10: =IF(H10=0,"n/m",I10/ABS(H10)) -> -0.03271028 | K10: =IF(J10="n/m","n/m - see note",IF(AND(ABS(I10)>=Inputs!$H$37,ABS(J10)>=Inputs!$H$38),IF(I10<0,"Favorable - material","UNFAVORABLE - material"),""))
A11: A&H Contribution Margin | B11: =B9-B10 -> 451 | C11: =C9-C10 -> 538 | D11: =B11-C11 -> -87 | E11: =IF(C11=0,"n/m",D11/ABS(C11)) -> -0.16171004 | F11: =IF(E11="n/m","n/m - see note",IF(AND(ABS(D11)>=Inputs!$H$37,ABS(E11)>=Inputs!$H$38),IF(D11>0,"Favorable - material","UNFAVORABLE - material"),"")) -> UNFAVORABLE - material | G11: =G9-G10 -> 2450 | H11: =H9-H10 -> 2545 | I11: =G11-H11 -> -95 | J11: =IF(H11=0,"n/m",I11/ABS(H11)) -> -0.037328094 | K11: =IF(J11="n/m","n/m - see note",IF(AND(ABS(I11)>=Inputs!$H$37,ABS(J11)>=Inputs!$H$38),IF(I11>0,"Favorable - material","UNFAVORABLE - material"),""))
A12: ENTERPRISE SAAS
A13: Liquid Network Fees | B13: =Data_Actuals!$H$8 -> 510 | C13: =Data_Budget!$H$8 -> 430 | D13: =B13-C13 -> 80 | E13: =IF(C13=0,"n/m",D13/ABS(C13)) -> 0.18604651 | F13: =IF(E13="n/m","n/m - see note",IF(AND(ABS(D13)>=Inputs!$H$37,ABS(E13)>=Inputs!$H$38),IF(D13>0,"Favorable - material","UNFAVORABLE - material"),"")) -> Favorable - material | G13: =SUM(Data_Actuals!$D$8:$H$8) -> 2090 | H13: =SUM(Data_Budget!$D$8:$H$8) -> 2000 | I13: =G13-H13 -> 90 | J13: =IF(H13=0,"n/m",I13/ABS(H13)) -> 0.045 | K13: =IF(J13="n/m","n/m - see note",IF(AND(ABS(I13)>=Inputs!$H$37,ABS(J13)>=Inputs!$H$38),IF(I13>0,"Favorable - material","UNFAVORABLE - material"),""))
A14: Blockstream AMP (SaaS) | B14: =Data_Actuals!$H$9 -> 1380 | C14: =Data_Budget!$H$9 -> 1390 | D14: =B14-C14 -> -10 | E14: =IF(C14=0,"n/m",D14/ABS(C14)) -> -0.0071942446 | F14: =IF(E14="n/m","n/m - see note",IF(AND(ABS(D14)>=Inputs!$H$37,ABS(E14)>=Inputs!$H$38),IF(D14>0,"Favorable - material","UNFAVORABLE - material"),"")) | G14: =SUM(Data_Actuals!$D$9:$H$9) -> 6565 | H14: =SUM(Data_Budget!$D$9:$H$9) -> 6550 | I14: =G14-H14 -> 15 | J14: =IF(H14=0,"n/m",I14/ABS(H14)) -> 0.0022900763 | K14: =IF(J14="n/m","n/m - see note",IF(AND(ABS(I14)>=Inputs!$H$37,ABS(J14)>=Inputs!$H$38),IF(I14>0,"Favorable - material","UNFAVORABLE - material"),""))
A15: Enterprise Infrastructure & Licensing | B15: =Data_Actuals!$H$10 -> 705 | C15: =Data_Budget!$H$10 -> 660 | D15: =B15-C15 -> 45 | E15: =IF(C15=0,"n/m",D15/ABS(C15)) -> 0.068181818 | F15: =IF(E15="n/m","n/m - see note",IF(AND(ABS(D15)>=Inputs!$H$37,ABS(E15)>=Inputs!$H$38),IF(D15>0,"Favorable - material","UNFAVORABLE - material"),"")) | G15: =SUM(Data_Actuals!$D$10:$H$10) -> 3300 | H15: =SUM(Data_Budget!$D$10:$H$10) -> 3200 | I15: =G15-H15 -> 100 | J15: =IF(H15=0,"n/m",I15/ABS(H15)) -> 0.03125 | K15: =IF(J15="n/m","n/m - see note",IF(AND(ABS(I15)>=Inputs!$H$37,ABS(J15)>=Inputs!$H$38),IF(I15>0,"Favorable - material","UNFAVORABLE - material"),""))
A16: Enterprise Revenue | B16: =SUM(B13:B15) -> 2595 | C16: =SUM(C13:C15) -> 2480 | D16: =B16-C16 -> 115 | E16: =IF(C16=0,"n/m",D16/ABS(C16)) -> 0.046370968 | F16: =IF(E16="n/m","n/m - see note",IF(AND(ABS(D16)>=Inputs!$H$37,ABS(E16)>=Inputs!$H$38),IF(D16>0,"Favorable - material","UNFAVORABLE - material"),"")) | G16: =SUM(G13:G15) -> 11955 | H16: =SUM(H13:H15) -> 11750 | I16: =G16-H16 -> 205 | J16: =IF(H16=0,"n/m",I16/ABS(H16)) -> 0.017446809 | K16: =IF(J16="n/m","n/m - see note",IF(AND(ABS(I16)>=Inputs!$H$37,ABS(J16)>=Inputs!$H$38),IF(I16>0,"Favorable - material","UNFAVORABLE - material"),""))
A17: Hosting & Infrastructure | B17: =Data_Actuals!$H$13 -> 360 | C17: =Data_Budget!$H$13 -> 340 | D17: =B17-C17 -> 20 | E17: =IF(C17=0,"n/m",D17/ABS(C17)) -> 0.058823529 | F17: =IF(E17="n/m","n/m - see note",IF(AND(ABS(D17)>=Inputs!$H$37,ABS(E17)>=Inputs!$H$38),IF(D17<0,"Favorable - material","UNFAVORABLE - material"),"")) | G17: =SUM(Data_Actuals!$D$13:$H$13) -> 1670 | H17: =SUM(Data_Budget!$D$13:$H$13) -> 1650 | I17: =G17-H17 -> 20 | J17: =IF(H17=0,"n/m",I17/ABS(H17)) -> 0.012121212 | K17: =IF(J17="n/m","n/m - see note",IF(AND(ABS(I17)>=Inputs!$H$37,ABS(J17)>=Inputs!$H$38),IF(I17<0,"Favorable - material","UNFAVORABLE - material"),""))
A18: Enterprise Contribution Margin | B18: =B16-B17 -> 2235 | C18: =C16-C17 -> 2140 | D18: =B18-C18 -> 95 | E18: =IF(C18=0,"n/m",D18/ABS(C18)) -> 0.044392523 | F18: =IF(E18="n/m","n/m - see note",IF(AND(ABS(D18)>=Inputs!$H$37,ABS(E18)>=Inputs!$H$38),IF(D18>0,"Favorable - material","UNFAVORABLE - material"),"")) | G18: =G16-G17 -> 10285 | H18: =H16-H17 -> 10100 | I18: =G18-H18 -> 185 | J18: =IF(H18=0,"n/m",I18/ABS(H18)) -> 0.018316832 | K18: =IF(J18="n/m","n/m - see note",IF(AND(ABS(I18)>=Inputs!$H$37,ABS(J18)>=Inputs!$H$38),IF(I18>0,"Favorable - material","UNFAVORABLE - material"),""))
A19: TOTAL COMPANY
A20: Total Revenue | B20: =B9+B16 -> 3406 | C20: =C9+C16 -> 3473 | D20: =B20-C20 -> -67 | E20: =IF(C20=0,"n/m",D20/ABS(C20)) -> -0.019291679 | F20: =IF(E20="n/m","n/m - see note",IF(AND(ABS(D20)>=Inputs!$H$37,ABS(E20)>=Inputs!$H$38),IF(D20>0,"Favorable - material","UNFAVORABLE - material"),"")) | G20: =G9+G16 -> 16475 | H20: =H9+H16 -> 16435 | I20: =G20-H20 -> 40 | J20: =IF(H20=0,"n/m",I20/ABS(H20)) -> 0.0024338302 | K20: =IF(J20="n/m","n/m - see note",IF(AND(ABS(I20)>=Inputs!$H$37,ABS(J20)>=Inputs!$H$38),IF(I20>0,"Favorable - material","UNFAVORABLE - material"),""))
A21: Total COGS | B21: =B10+B17 -> 720 | C21: =C10+C17 -> 795 | D21: =B21-C21 -> -75 | E21: =IF(C21=0,"n/m",D21/ABS(C21)) -> -0.094339623 | F21: =IF(E21="n/m","n/m - see note",IF(AND(ABS(D21)>=Inputs!$H$37,ABS(E21)>=Inputs!$H$38),IF(D21<0,"Favorable - material","UNFAVORABLE - material"),"")) | G21: =G10+G17 -> 3740 | H21: =H10+H17 -> 3790 | I21: =G21-H21 -> -50 | J21: =IF(H21=0,"n/m",I21/ABS(H21)) -> -0.013192612 | K21: =IF(J21="n/m","n/m - see note",IF(AND(ABS(I21)>=Inputs!$H$37,ABS(J21)>=Inputs!$H$38),IF(I21<0,"Favorable - material","UNFAVORABLE - material"),""))
A22: Gross Profit | B22: =B20-B21 -> 2686 | C22: =C20-C21 -> 2678 | D22: =B22-C22 -> 8 | E22: =IF(C22=0,"n/m",D22/ABS(C22)) -> 0.002987304 | F22: =IF(E22="n/m","n/m - see note",IF(AND(ABS(D22)>=Inputs!$H$37,ABS(E22)>=Inputs!$H$38),IF(D22>0,"Favorable - material","UNFAVORABLE - material"),"")) | G22: =G20-G21 -> 12735 | H22: =H20-H21 -> 12645 | I22: =G22-H22 -> 90 | J22: =IF(H22=0,"n/m",I22/ABS(H22)) -> 0.0071174377 | K22: =IF(J22="n/m","n/m - see note",IF(AND(ABS(I22)>=Inputs!$H$37,ABS(J22)>=Inputs!$H$38),IF(I22>0,"Favorable - material","UNFAVORABLE - material"),""))
A23: CORPORATE OPEX (unallocated)
A24: Personnel - R&D / Engineering | B24: =Data_Actuals!$H$14 -> 1975 | C24: =Data_Budget!$H$14 -> 1940 | D24: =B24-C24 -> 35 | E24: =IF(C24=0,"n/m",D24/ABS(C24)) -> 0.018041237 | F24: =IF(E24="n/m","n/m - see note",IF(AND(ABS(D24)>=Inputs!$H$37,ABS(E24)>=Inputs!$H$38),IF(D24<0,"Favorable - material","UNFAVORABLE - material"),"")) | G24: =SUM(Data_Actuals!$D$14:$H$14) -> 9555 | H24: =SUM(Data_Budget!$D$14:$H$14) -> 9400 | I24: =G24-H24 -> 155 | J24: =IF(H24=0,"n/m",I24/ABS(H24)) -> 0.016489362 | K24: =IF(J24="n/m","n/m - see note",IF(AND(ABS(I24)>=Inputs!$H$37,ABS(J24)>=Inputs!$H$38),IF(I24<0,"Favorable - material","UNFAVORABLE - material"),""))
A25: Personnel - Sales & Marketing | B25: =Data_Actuals!$H$15 -> 590 | C25: =Data_Budget!$H$15 -> 570 | D25: =B25-C25 -> 20 | E25: =IF(C25=0,"n/m",D25/ABS(C25)) -> 0.035087719 | F25: =IF(E25="n/m","n/m - see note",IF(AND(ABS(D25)>=Inputs!$H$37,ABS(E25)>=Inputs!$H$38),IF(D25<0,"Favorable - material","UNFAVORABLE - material"),"")) | G25: =SUM(Data_Actuals!$D$15:$H$15) -> 2820 | H25: =SUM(Data_Budget!$D$15:$H$15) -> 2750 | I25: =G25-H25 -> 70 | J25: =IF(H25=0,"n/m",I25/ABS(H25)) -> 0.025454545 | K25: =IF(J25="n/m","n/m - see note",IF(AND(ABS(I25)>=Inputs!$H$37,ABS(J25)>=Inputs!$H$38),IF(I25<0,"Favorable - material","UNFAVORABLE - material"),""))
A26: Personnel - G&A | B26: =Data_Actuals!$H$16 -> 450 | C26: =Data_Budget!$H$16 -> 435 | D26: =B26-C26 -> 15 | E26: =IF(C26=0,"n/m",D26/ABS(C26)) -> 0.034482759 | F26: =IF(E26="n/m","n/m - see note",IF(AND(ABS(D26)>=Inputs!$H$37,ABS(E26)>=Inputs!$H$38),IF(D26<0,"Favorable - material","UNFAVORABLE - material"),"")) | G26: =SUM(Data_Actuals!$D$16:$H$16) -> 2165 | H26: =SUM(Data_Budget!$D$16:$H$16) -> 2125 | I26: =G26-H26 -> 40 | J26: =IF(H26=0,"n/m",I26/ABS(H26)) -> 0.018823529 | K26: =IF(J26="n/m","n/m - see note",IF(AND(ABS(I26)>=Inputs!$H$37,ABS(J26)>=Inputs!$H$38),IF(I26<0,"Favorable - material","UNFAVORABLE - material"),""))
A27: Cloud & Infrastructure | B27: =Data_Actuals!$H$17 -> 480 | C27: =Data_Budget!$H$17 -> 300 | D27: =B27-C27 -> 180 | E27: =IF(C27=0,"n/m",D27/ABS(C27)) -> 0.6 | F27: =IF(E27="n/m","n/m - see note",IF(AND(ABS(D27)>=Inputs!$H$37,ABS(E27)>=Inputs!$H$38),IF(D27<0,"Favorable - material","UNFAVORABLE - material"),"")) -> UNFAVORABLE - material | G27: =SUM(Data_Actuals!$D$17:$H$17) -> 1810 | H27: =SUM(Data_Budget!$D$17:$H$17) -> 1450 | I27: =G27-H27 -> 360 | J27: =IF(H27=0,"n/m",I27/ABS(H27)) -> 0.24827586 | K27: =IF(J27="n/m","n/m - see note",IF(AND(ABS(I27)>=Inputs!$H$37,ABS(J27)>=Inputs!$H$38),IF(I27<0,"Favorable - material","UNFAVORABLE - material"),"")) -> UNFAVORABLE - material
A28: Marketing Programs | B28: =Data_Actuals!$H$18 -> 240 | C28: =Data_Budget!$H$18 -> 200 | D28: =B28-C28 -> 40 | E28: =IF(C28=0,"n/m",D28/ABS(C28)) -> 0.2 | F28: =IF(E28="n/m","n/m - see note",IF(AND(ABS(D28)>=Inputs!$H$37,ABS(E28)>=Inputs!$H$38),IF(D28<0,"Favorable - material","UNFAVORABLE - material"),"")) | G28: =SUM(Data_Actuals!$D$18:$H$18) -> 1000 | H28: =SUM(Data_Budget!$D$18:$H$18) -> 950 | I28: =G28-H28 -> 50 | J28: =IF(H28=0,"n/m",I28/ABS(H28)) -> 0.052631579 | K28: =IF(J28="n/m","n/m - see note",IF(AND(ABS(I28)>=Inputs!$H$37,ABS(J28)>=Inputs!$H$38),IF(I28<0,"Favorable - material","UNFAVORABLE - material"),""))
A29: Travel & Events | B29: =Data_Actuals!$H$19 -> 175 | C29: =Data_Budget!$H$19 -> 80 | D29: =B29-C29 -> 95 | E29: =IF(C29=0,"n/m",D29/ABS(C29)) -> 1.1875 | F29: =IF(E29="n/m","n/m - see note",IF(AND(ABS(D29)>=Inputs!$H$37,ABS(E29)>=Inputs!$H$38),IF(D29<0,"Favorable - material","UNFAVORABLE - material"),"")) -> UNFAVORABLE - material | G29: =SUM(Data_Actuals!$D$19:$H$19) -> 503 | H29: =SUM(Data_Budget!$D$19:$H$19) -> 370 | I29: =G29-H29 -> 133 | J29: =IF(H29=0,"n/m",I29/ABS(H29)) -> 0.35945946 | K29: =IF(J29="n/m","n/m - see note",IF(AND(ABS(I29)>=Inputs!$H$37,ABS(J29)>=Inputs!$H$38),IF(I29<0,"Favorable - material","UNFAVORABLE - material"),"")) -> UNFAVORABLE - material
A30: Professional Services | B30: =Data_Actuals!$H$20 -> 165 | C30: =Data_Budget!$H$20 -> 120 | D30: =B30-C30 -> 45 | E30: =IF(C30=0,"n/m",D30/ABS(C30)) -> 0.375 | F30: =IF(E30="n/m","n/m - see note",IF(AND(ABS(D30)>=Inputs!$H$37,ABS(E30)>=Inputs!$H$38),IF(D30<0,"Favorable - material","UNFAVORABLE - material"),"")) | G30: =SUM(Data_Actuals!$D$20:$H$20) -> 690 | H30: =SUM(Data_Budget!$D$20:$H$20) -> 560 | I30: =G30-H30 -> 130 | J30: =IF(H30=0,"n/m",I30/ABS(H30)) -> 0.23214286 | K30: =IF(J30="n/m","n/m - see note",IF(AND(ABS(I30)>=Inputs!$H$37,ABS(J30)>=Inputs!$H$38),IF(I30<0,"Favorable - material","UNFAVORABLE - material"),"")) -> UNFAVORABLE - material
A31: Software & Tools | B31: =Data_Actuals!$H$21 -> 92 | C31: =Data_Budget!$H$21 -> 84 | D31: =B31-C31 -> 8 | E31: =IF(C31=0,"n/m",D31/ABS(C31)) -> 0.095238095 | F31: =IF(E31="n/m","n/m - see note",IF(AND(ABS(D31)>=Inputs!$H$37,ABS(E31)>=Inputs!$H$38),IF(D31<0,"Favorable - material","UNFAVORABLE - material"),"")) | G31: =SUM(Data_Actuals!$D$21:$H$21) -> 425 | H31: =SUM(Data_Budget!$D$21:$H$21) -> 408 | I31: =G31-H31 -> 17 | J31: =IF(H31=0,"n/m",I31/ABS(H31)) -> 0.041666667 | K31: =IF(J31="n/m","n/m - see note",IF(AND(ABS(I31)>=Inputs!$H$37,ABS(J31)>=Inputs!$H$38),IF(I31<0,"Favorable - material","UNFAVORABLE - material"),""))
A32: Facilities | B32: =Data_Actuals!$H$22 -> 115 | C32: =Data_Budget!$H$22 -> 112 | D32: =B32-C32 -> 3 | E32: =IF(C32=0,"n/m",D32/ABS(C32)) -> 0.026785714 | F32: =IF(E32="n/m","n/m - see note",IF(AND(ABS(D32)>=Inputs!$H$37,ABS(E32)>=Inputs!$H$38),IF(D32<0,"Favorable - material","UNFAVORABLE - material"),"")) | G32: =SUM(Data_Actuals!$D$22:$H$22) -> 559 | H32: =SUM(Data_Budget!$D$22:$H$22) -> 554 | I32: =G32-H32 -> 5 | J32: =IF(H32=0,"n/m",I32/ABS(H32)) -> 0.0090252708 | K32: =IF(J32="n/m","n/m - see note",IF(AND(ABS(I32)>=Inputs!$H$37,ABS(J32)>=Inputs!$H$38),IF(I32<0,"Favorable - material","UNFAVORABLE - material"),""))
A33: Other OpEx | B33: =Data_Actuals!$H$23 -> 60 | C33: =Data_Budget!$H$23 -> 50 | D33: =B33-C33 -> 10 | E33: =IF(C33=0,"n/m",D33/ABS(C33)) -> 0.2 | F33: =IF(E33="n/m","n/m - see note",IF(AND(ABS(D33)>=Inputs!$H$37,ABS(E33)>=Inputs!$H$38),IF(D33<0,"Favorable - material","UNFAVORABLE - material"),"")) | G33: =SUM(Data_Actuals!$D$23:$H$23) -> 236 | H33: =SUM(Data_Budget!$D$23:$H$23) -> 236 | I33: =G33-H33 -> 0 | J33: =IF(H33=0,"n/m",I33/ABS(H33)) -> 0 | K33: =IF(J33="n/m","n/m - see note",IF(AND(ABS(I33)>=Inputs!$H$37,ABS(J33)>=Inputs!$H$38),IF(I33<0,"Favorable - material","UNFAVORABLE - material"),""))
A34: Total OpEx | B34: =SUM(B24:B33) -> 4342 | C34: =SUM(C24:C33) -> 3891 | D34: =B34-C34 -> 451 | E34: =IF(C34=0,"n/m",D34/ABS(C34)) -> 0.11590851 | F34: =IF(E34="n/m","n/m - see note",IF(AND(ABS(D34)>=Inputs!$H$37,ABS(E34)>=Inputs!$H$38),IF(D34<0,"Favorable - material","UNFAVORABLE - material"),"")) -> UNFAVORABLE - material | G34: =SUM(G24:G33) -> 19763 | H34: =SUM(H24:H33) -> 18803 | I34: =G34-H34 -> 960 | J34: =IF(H34=0,"n/m",I34/ABS(H34)) -> 0.051055683 | K34: =IF(J34="n/m","n/m - see note",IF(AND(ABS(I34)>=Inputs!$H$37,ABS(J34)>=Inputs!$H$38),IF(I34<0,"Favorable - material","UNFAVORABLE - material"),""))
A35: Operating Profit (before treasury) | B35: =B22-B34 -> -1656 | C35: =C22-C34 -> -1213 | D35: =B35-C35 -> -443 | E35: =IF(C35=0,"n/m",D35/ABS(C35)) -> -0.36521022 | F35: =IF(E35="n/m","n/m - see note",IF(AND(ABS(D35)>=Inputs!$H$37,ABS(E35)>=Inputs!$H$38),IF(D35>0,"Favorable - material","UNFAVORABLE - material"),"")) -> UNFAVORABLE - material | G35: =G22-G34 -> -7028 | H35: =H22-H34 -> -6158 | I35: =G35-H35 -> -870 | J35: =IF(H35=0,"n/m",I35/ABS(H35)) -> -0.14127964 | K35: =IF(J35="n/m","n/m - see note",IF(AND(ABS(I35)>=Inputs!$H$37,ABS(J35)>=Inputs!$H$38),IF(I35>0,"Favorable - material","UNFAVORABLE - material"),"")) -> UNFAVORABLE - material
A36: BTC Treasury Mark-to-Market | B36: =Data_Actuals!$H$11 -> 1450 | C36: =Data_Budget!$H$11 -> 0 | D36: =B36-C36 -> 1450 | E36: =IF(C36=0,"n/m",D36/ABS(C36)) -> n/m | F36: =IF(E36="n/m","n/m - see note",IF(AND(ABS(D36)>=Inputs!$H$37,ABS(E36)>=Inputs!$H$38),IF(D36>0,"Favorable - material","UNFAVORABLE - material"),"")) -> n/m - see note | G36: =SUM(Data_Actuals!$D$11:$H$11) -> 2300 | H36: =SUM(Data_Budget!$D$11:$H$11) -> 0 | I36: =G36-H36 -> 2300 | J36: =IF(H36=0,"n/m",I36/ABS(H36)) -> n/m | K36: =IF(J36="n/m","n/m - see note",IF(AND(ABS(I36)>=Inputs!$H$37,ABS(J36)>=Inputs!$H$38),IF(I36>0,"Favorable - material","UNFAVORABLE - material"),"")) -> n/m - see note
A37: Net Result incl. treasury mark | B37: =B35+B36 -> -206 | C37: =C35+C36 -> -1213 | D37: =B37-C37 -> 1007 | E37: =IF(C37=0,"n/m",D37/ABS(C37)) -> 0.83017312 | F37: =IF(E37="n/m","n/m - see note",IF(AND(ABS(D37)>=Inputs!$H$37,ABS(E37)>=Inputs!$H$38),IF(D37>0,"Favorable - material","UNFAVORABLE - material"),"")) -> Favorable - material | G37: =G35+G36 -> -4728 | H37: =H35+H36 -> -6158 | I37: =G37-H37 -> 1430 | J37: =IF(H37=0,"n/m",I37/ABS(H37)) -> 0.23221825 | K37: =IF(J37="n/m","n/m - see note",IF(AND(ABS(I37)>=Inputs!$H$37,ABS(J37)>=Inputs!$H$38),IF(I37>0,"Favorable - material","UNFAVORABLE - material"),"")) -> Favorable - material
A39: Why the treasury mark cannot sit inside a % variance read: it is budgeted at $0 every month by design, so any actual mark produces an undefined (÷0) or meaningless percentage - and in up-months it flatters the total. It is therefore shown as a separate reconciling line BELOW operating profit; operating variances above are clean of it.

Sheet Tie-Out
A1: Tie-Out - six reviewer-relevant figures reconciled to exact source cells
A2: Column C pulls the figure from the model cell named in column B. Column D recomputes it independently from the raw data tabs. Column F must read TIE on every row before the pack ships. All $000s.
A4: Figure | B4: Model cell | C4: Model value | D4: Independent recompute from raw data | E4: Delta | F4: Status
A5: May 2026 Total Revenue | B5: BvA!B20 | C5: =BvA!B20 -> 3406 | D5: =Data_Actuals!H5+Data_Actuals!H6+Data_Actuals!H7+Data_Actuals!H8+Data_Actuals!H9+Data_Actuals!H10 -> 3406 | E5: =C5-D5 -> 0 | F5: =IF(ROUND(E5,6)=0,"TIE","BREAK") -> TIE
A6: May 2026 Operating Profit (before treasury) | B6: BvA!B35 | C6: =BvA!B35 -> -1656 | D6: =Data_Actuals!H5+Data_Actuals!H6+Data_Actuals!H7+Data_Actuals!H8+Data_Actuals!H9+Data_Actuals!H10-(Data_Actuals!H12+Data_Actuals!H13)-(Data_Actuals!H14+Data_Actuals!H15+Data_Actuals!H16+Data_Actuals!H17+Data_Actuals!H18+Data_Actuals!H19+Data_Actuals!H20+Data_Actuals!H21+Data_Actuals!H22+Data_Actuals!H23) -> -1656 | E6: =C6-D6 -> 0 | F6: =IF(ROUND(E6,6)=0,"TIE","BREAK") -> TIE
A7: YTD (Jan–May) Operating Profit (before treasury) | B7: BvA!G35 | C7: =BvA!G35 -> -7028 | D7: =SUM(Data_Actuals!D5:H5)+SUM(Data_Actuals!D6:H6)+SUM(Data_Actuals!D7:H7)+SUM(Data_Actuals!D8:H8)+SUM(Data_Actuals!D9:H9)+SUM(Data_Actuals!D10:H10)-(SUM(Data_Actuals!D12:H12)+SUM(Data_Actuals!D13:H13))-(SUM(Data_Actuals!D14:H14)+SUM(Data_Actuals!D15:H15)+SUM(Data_Actuals!D16:H16)+SUM(Data_Actuals!D17:H17)+SUM(Data_Actuals!D18:H18)+SUM(Data_Actuals!D19:H19)+SUM(Data_Actuals!D20:H20)+SUM(Data_Actuals!D21:H21)+SUM(Data_Actuals!D22:H22)+SUM(Data_Actuals!D23:H23)) -> -7028 | E7: =C7-D7 -> 0 | F7: =IF(ROUND(E7,6)=0,"TIE","BREAK") -> TIE
A8: YTD BTC Treasury Mark-to-Market | B8: BvA!G36 | C8: =BvA!G36 -> 2300 | D8: =SUM(Data_Actuals!D11:H11) -> 2300 | E8: =C8-D8 -> 0 | F8: =IF(ROUND(E8,6)=0,"TIE","BREAK") -> TIE
A9: May GL total - Blockstream AMP (SaaS) vs reported | B9: GL_Recon!B7 | C9: =GL_Recon!B7 -> 1380 | D9: =Data_Actuals!H9 -> 1380 | E9: =C9-D9 -> 0 | F9: =IF(ROUND(E9,6)=0,"TIE","BREAK") -> TIE
A10: Base FY Operating Result (scenario cell) | B10: Forecast!H5 | C10: =Forecast!H5 -> -17359.332 | D10: =Forecast!N39 -> -17359.332 | E10: =C10-D10 -> 0 | F10: =IF(ROUND(E10,6)=0,"TIE","BREAK") -> TIE
A12: Row 5 note: the AMP GL total ties to the reported P&L - completeness is proven - while GL_Recon Issue 3 shows $132K of it is recognized in the wrong period. Footing and correctness are different tests; this pack runs both.
A15: Bear FY Operating Result and Swing (Forecast!H6, Forecast!H7) derive from the same driver grid as row 10 and recalculate on any flip of Inputs!H5 / H6.

Sheet GL_Recon
A1: NetSuite GL → Reported May P&L Reconciliation (the human-in-the-loop control)
A2: Five accounts. Step 1: foot the GL to the reported figure. Step 2: read the support (dates, terms, invoice refs, counterparties) - two accounts foot cleanly but contain entries recognized in the wrong period or incorrectly. All $000s. GL totals are live SUMIFS on GL_Detail; reported figures are links to Data_Actuals.
A4: Account | B4: GL total (SUMIFS) | C4: Reported May P&L | D4: Footing diff | E4: Foots? | F4: Substance finding after reading support
A5: Cloud & Infrastructure | B5: =SUMIFS(GL_Detail!$I$5:$I$27,GL_Detail!$C$5:$C$27,"Cloud & Infrastructure") -> 510 | C5: =Data_Actuals!$H$17 -> 480 | D5: =B5-C5 -> 30 | E5: =IF(D5=0,"TIES","BREAK") -> BREAK | F5: DOES NOT FOOT - duplicate invoice (JE-1147). See Issue 1.
A6: Travel & Events | B6: =SUMIFS(GL_Detail!$I$5:$I$27,GL_Detail!$C$5:$C$27,"Travel & Events") -> 175 | C6: =Data_Actuals!$H$19 -> 175 | D6: =B6-C6 -> 0 | E6: =IF(D6=0,"TIES","BREAK") -> TIES | F6: Foots, but $150K belongs in June - cut-off error (JE-1203). See Issue 2.
